<?xml version="1.0"?>
<robot name="my_robot">
    <material name="grey">
        <color rgba="0.7 0.7 0.7 1.0"/>
    </material>
    <material name="green">
        <color rgba="0.0 0.6 0.0 1.0"/>
    </material>
    <material name="white">
        <color rgba="1.0 1.0 1.0 1.0"/>
    </material>
    <link name="base_footprint"/>
    <link name="base_link">
        <visual>
            <geometry>
                <box size="0.6 0.4 0.2"/>
            </geometry>
            <origin xyz="0 0 0.1 " rpy="0 0 0 "/>
            <material name="green"/>
        </visual>
    </link>
    <joint name="base_joint" type="fixed">
        <parent link="base_footprint"/>
        <child link="base_link"/>
        <origin xyz="0 0 0.1" rpy="0 0 0 "/>
    </joint>
    <link name="lidar_link">
        <visual>
            <geometry>
                <cylinder radius="0.1" length="0.05"/>    
            </geometry>
            <origin xyz="0 0 0 " rpy="0 0 0 "/>
            <material name="white"/>
        </visual>
    </link>
    <joint name="base_to_lidar" type="fixed">
        <parent link="base_link"/>
        <child link="lidar_link"/>
        <origin xyz="0 0 0.225" rpy="0 0 0 "/>
    </joint>
    <link name="left_wheel">
        <visual>
            <geometry>
                <cylinder radius="0.1" length="0.05"/>
            </geometry>
            <material name="grey"/>
            <origin xyz="0 0 0" rpy="1.57 0 0 "/> 
        </visual>
    </link>
    <joint name="base_to_left_wheel" type="continuous">
        <parent link="base_link"/>
        <child link="left_wheel"/>
        <origin xyz="-0.15 0.225 0 " rpy="0 0 0 "/>
        <axis xyz="0 1 0"/>
    </joint>
    <link name="right_wheel">
        <visual>
            <geometry>
                <cylinder radius="0.1" length="0.05"/>
            </geometry>
            <material name="grey"/>
            <origin xyz="0 0 0" rpy="1.57 0 0 "/> 
        </visual>
    </link>
    <joint name="base_to_right_wheel" type="continuous">
        <parent link="base_link"/>
        <child link="right_wheel"/>
        <origin xyz="-0.15 -0.225 0 " rpy="0 0 0 "/>
        <axis xyz="0 1 0"/>
    </joint>
    <link name="caster_wheel">
        <visual>
            <geometry>
                <sphere radius="0.05"/>
            </geometry>
            <origin xyz=" 0 0 0 " />
            <material name="grey"/>
        </visual>
    </link>
    <joint name="base_to_caster" type="fixed">
        <parent link="base_link"/>
        <child link="caster_wheel"/>
        <origin xyz="0.15 0 -0.05 " rpy="0 0 0 "/>
    </joint>
</robot>